Workbook

Sheet Key Steps in M&A Process
A1: Key Steps in M&A
A2: 1 | B2: Define Strategic Objectives
A3: 2 | B3: How Does M&A fit into these
A4: 3 | B4: Define M&A Principles (TBVS dilution, EPS Accretion, Workback minimums and Targets)
A5: 4 | B5: Conduct Situation Assessment (Are we a CAMELS "2", do we have enough capital, earnings, and corporate structure)
A6: 5 | B6: Who are the Targets and do any of them meet the strategic objectives
A7: 6 | B7: Model the combined company and discuss the pros and cons
A8: 7 | B8: What are we getting in value vs. the execution risk
B13: Adapted for GSBC BankSim

Sheet Sim M&A Checklist-Metrics Check
B1: GSBC Sim M&A Checklist | C1: Initial When Complete
A2: 1 | B2: Identify & summarize how & why a merger or acqusition would fit into your strategic objectives
A3: 2 | B3: Select at least one bank in your community to analyze for acquistion and/or "merger of equals"
A4: 3 | B4: Model the acquisition under one or multiple scenarios (please understand that a Bank will only accept a value greater than their trading value - usually 20% - 30% more) - See B550
A5: 4 | B5: Review the combined company and discuss pro's & con's
A6: 5 | B6: Review Model outcomes against the Issues List
A7: 6 | B7: Consider & Plan Post Merger Executive Management team - including opportunities, challenges and risks
A8: 7 | B8: Determine if you wish to seek Regulatory (Instructor) Approval
A9: 8 | B9: If necessary, address any obstacles identified by Regulator (Instructor) & rerun model
A10: 9 | B10: Seek Regulatory Approval and/or Decide to Move Forward or Abandon Opportunity
A11: 10 | B11: Evaluate what you would be getting in value vs. the possible execution risks (i.e., both financial & non-financial - loss of key officers, etc.)
A12: 11 | B12: Address what you learned in this exercise in one or two slides in your Shareholder Presentation
D14: "Go" to "No Go" Range
B15: GSBC SIM Key M&A Components - Check Against Key Financial Metrics | D15: "Go or Discuss" Range | E15: "No Go"- Must Have Reason
A16: 1 | B16: Target Bank CAMELS Composite Rating - Most recent exam - PLEASE INPUT | C16: 3 | D16: <4 | E16: >3
A17: 2 | B17: Buyer Bank CAMELS Composite Rating - Most recent exam - PLEASE INPUT | C17: 2 | D17: <3 | E17: >2
A18: 3 | B18: Post Merger Tangible Common Equity/Tangible Assets - See Model - Row 39 Column G | C18: =Model!G39 -> 0.080188076 | D18: >5.99% | E18: <6.00%
A19: 4 | B19: Tangible Book Value Per Share (TBVS) Workback Period - See Assumptions - Line 4, Column F & G | C19: =Model!L39 -> 4 | D19: <5.00 | E19: >5.01
A20: 5 | B20: Immediately Core Earnings Accretive (excluding one time charges) - See Assumptions - Row 3, Column F & G | C20: =Model!I69 -> 0.85 | D20: >0.01 | E20: <0
A21: 6 | B21: Tangible Book Value Per Share (TBVS) Dilution % - See Assumptions - Row 2, Column F & G | C21: =Model!J37 -> -0.083703062 | D21: >-10.00% | E21: <-10.01%
A22: 7 | B22: Cost Savings % Used - See Assumptions Row 13, Column C | C22: =Assumptions!C13 -> 0.3 | D22: <40.00% | E22: >40.01%
A23: 8 | B23: Deal Expense % Used - See Assumptions Row 14, Column C | C23: =Assumptions!C14 -> 0.08 | D23: <12.00% | E23: >12.01%
A24: 9 | B24: Buyers Stock Price to TBVS - See Assumptions Row 18, Column F & G | C24: =Assumptions!F25 -> 1.0830991 | D24: >100.0% | E24: <100%
A25: 10 | B25: Core Deposit Intangible (CDI) % - See Assumptions Row 19, Column C | C25: =Assumptions!C17 -> 0.02 | D25: <4.0% | E25: >4.01%

Sheet Model
I1: Any Issues:
B2: ="Total Transaction Value: "&TEXT(Assumptions!$C$25*D36/1000000,"$0.0")&" million" -> Total Transaction Value: $57.3 million | E2: ="TBVS Dilution: "&TEXT(I37,"$0.00")&" or "&TEXT(J37,"0.0%") -> TBVS Dilution: -$3.37 or -8.4% | I2: =IF(J37<-10%,"Issue: Too Much TBVS Dilution","")
B3: ="P/TBVS = "&TEXT(Assumptions!$F$25,"0.0%") -> P/TBVS = 108.3% | E3: ="Cash EPS Accretion: "&TEXT(I69,"$0.00")&" or "&TEXT(J69,"0.0%") -> Cash EPS Accretion: $0.85 or 25.4% | I3: =IF(G69<B69,"Issue: Not Immediately Accretive","")
B4: ="P/EPS = "&TEXT(Assumptions!$H$25,"0.0") -> P/EPS = 24.8 | E4: ="TBVS Workback: "&TEXT(I38,"$0.00") -> TBVS Workback: 4 Years | I4: =IF(I37>0,"",IF(ROUND(I37*-1/I69,1)>5,"Issue: Work Back Too Long",IF(ROUND(I37*-1/I69,1)<0,"Potential Issue: Negative Workback","")))
B5: ="P/MVS = "&TEXT(Assumptions!$F$26,"0.0%") -> P/MVS = 124.7% | E5: ="Cost Savings: "&TEXT(-E51,"$0.0")&" million or "&TEXT(Assumptions!$C$13,"0.0%") -> Cost Savings: $6.2 million or 30.0%
B6: =TEXT(Assumptions!$C$11,"0.0%")&" Stock / "&TEXT(Assumptions!$C$12,"0.0%")&" Cash" -> 100.0% Stock / 0.0% Cash | E6: ="Deal Expenses: "&TEXT(-Assumptions!D43-Assumptions!E43,"$0.0")&" million or "&TEXT(Assumptions!$C$14,"0.0%") -> Deal Expenses: $4.6 million or 8.0%
A7: Adapted for GSBC BankSim | B7: Bank 1 - Bottom of the Barrel Bank | D7: Bank 4 | E7: Transaction Adjustments | G7: Combined
A8: Balance Sheet (millions) | C8: Report Reference
A9: Cash and Due From | B9: 49.8 | C9: B021 | D9: 42.2 | E9: =Assumptions!H43 -> -4.5836756 | G9: =SUM(B9:F9) -> 87.416324
A10: Federal Funds Sold | B10: 21.7 | C10: B021 | D10: 0 | E10: =Assumptions!H44 -> 0 | G10: =SUM(B10:F10) -> 21.7
A11: Securities | B11: 45 | C11: B021 | D11: 63.5 | E11: =Assumptions!H45 -> 0 | G11: =SUM(B11:F11) -> 108.5
A12: Loans (Gross) | B12: =B14-B13 -> 670.8 | C12: Calculated | D12: =D14-D13 -> 550 | E12: =Assumptions!H46 -> -9.3 | G12: =SUM(B12:F12) -> 1211.5
A13: Allowance for Credit Losses (enter a negative) | B13: -7.6 | C13: Handout | D13: -6.2 | E13: =Assumptions!H47 -> 6.2 | G13: =SUM(B13:F13) -> -7.6
A14: Loans (Net) | B14: 663.2 | C14: B021 | D14: 543.8 | E14: =Assumptions!H48 -> -3.1 | G14: =SUM(B14:F14) -> 1203.9
A15: Premises (Net) | B15: 5.3 | C15: B021 | D15: 5.1 | E15: =Assumptions!H49 -> 0 | G15: =SUM(B15:F15) -> 10.4
A16: Other Assets | B16: 33 | C16: B021 | D16: 29.7 | E16: =Assumptions!H50 -> -0.38909959 | G16: =SUM(B16:F16) -> 62.3109
A17: Total Intangibles | B17: 0 | C17: Calculated | D17: 0 | E17: =Assumptions!H51 -> 6.7174111 | G17: =SUM(B17:F17) -> 6.7174111
A18: Total Assets | B18: =SUM(B9:B11)+SUM(B14:B17) -> 818 | C18: Calculated | D18: =SUM(D9:D11)+SUM(D14:D17) -> 684.3 | E18: =SUM(E9:E11)+SUM(E14:E17) -> -1.3553641 | G18: =SUM(B18:F18) -> 1500.9446
A20: "Core" (non-maturity) Deposits | B20: =B22-B21 -> 542.8 | C20: Calculated | D20: =D22-D21 -> 456.2 | E20: =Assumptions!H54 -> 0 | G20: =SUM(B20:F20) -> 999
A21: Retail/Public/Brokered CDs | B21: 115.2 | C21: B021 | D21: 119.2 | E21: =Assumptions!H55 -> 0 | G21: =SUM(B21:F21) -> 234.4
A22: Total Deposits | B22: 658 | C22: B021 | D22: 575.4 | E22: =Assumptions!H56 -> 0 | G22: =SUM(B22:F22) -> 1233.4
A23: Borrowed Funds | B23: 50 | C23: B021 | D23: 30.1 | E23: =Assumptions!H57 -> 0 | G23: =SUM(B23:F23) -> 80.1
A24: Other Liabilities | B24: 30 | C24: B021 | D24: 26 | E24: =Assumptions!H58 -> 0 | G24: =SUM(B24:F24) -> 56
A25: Long-Term Debt | B25: 0 | C25: B021 | D25: 0 | E25: =Assumptions!H59 -> 0 | G25: =SUM(B25:F25) -> 0
A26: Subordinated Debt | B26: 5 | C26: B021 | D26: 0 | E26: =Assumptions!H60 -> 0 | G26: =SUM(B26:F26) -> 5
A27: Total Liabilities | B27: =SUM(B22:B26) -> 743 | C27: Calculated | D27: =SUM(D22:D26) -> 631.5 | E27: =SUM(E22:E26) -> 0 | G27: =SUM(B27:F27) -> 1374.5
A29: Owners Equity | B29: 75 | C29: B021 | D29: 52.9 | E29: =Assumptions!H63 -> -1.3553641 | G29: =SUM(B29:F29) -> 126.54464
A30: Total Equity | B30: =B29 -> 75 | C30: Calculated | D30: =D29 -> 52.9 | E30: =E29 -> -1.3553641 | G30: =SUM(B30:F30) -> 126.54464
G31: =SUM(B31:F31) -> 0
A32: Total Liabilities and Equity | B32: =B27+B30 -> 818 | C32: Calculated | D32: =D27+D30 -> 684.4 | E32: =E27+E30 -> -1.3553641 | G32: =SUM(B32:F32) -> 1501.0446
A34: =IF(OR(B34>=0.11,B34<=-0.11,D34>=0.11,D34<=-0.11),"OUT OF BALANCE!!!","") | B34: =B18-B32 -> 0 | D34: =D18-D32 -> -0.1
A35: Balance Sheet Per Share Metrics and Acc / (Dil) | C35: Report Reference | I35: Acc / (Dil)
A36: Common Shares Outstanding | B36: 1862897 | C36: B550 | D36: 1169305 | E36: =Assumptions!H68 -> 215993.48 | G36: =SUM(B36:F36) -> 3248195.5
A37: Stock Price/Share | B37: 41.36 | C37: B550 | D37: 39.29 | I37: =G38-B38 -> -3.3698748 | J37: =I37/B38 -> -0.083703062
A38: Tangible Book Value Per Share | B38: =(B29-B17)*1000000/B36 -> 40.259875 | C38: Calculated | D38: =(D29-D17)*1000000/D36 -> 45.240549 | G38: =ROUND((G29-G17)*1000000/G36,2) -> 36.89 | I38: =IF(I37>0,0,CONCATENATE(ROUND(I37*-1/I69,1)," Years")) -> 4 Years
A39: Tangible Common Equity/Tangible Assets | B39: =(B30-B17)/(B18-B17) -> 0.091687042 | C39: Calculated | D39: =(D30-D17)/(D18-D17) -> 0.077305275 | G39: =(G29-G17)/(G32-G17) -> 0.080188076 | L39: =IF(I37>0,0,ROUND(I37*-1/I69,1)) -> 4
A40: Price / Tangible Book Value Per Share | B40: =B37/B38 -> 1.0273256 | C40: Calculated | D40: =D37/D38 -> 0.86846869
A42: Income Statement (millions) | C42: Report Reference
B43: *Please be sure to use the Annual/YTD columns on the right-hand side of the Report.
A44: Interest Income | B44: 47.1 | C44: B022 | D44: 36.9 | E44: =(E9+E10)*Assumptions!C19 -> -0.17555478 | G44: =SUM(B44:F44) -> 83.824445
...

Sheet Assumptions
I1: =Model!I1 -> Any Issues:
C2: =Model!B2 -> Total Transaction Value: $57.3 million | F2: =Model!E2 -> TBVS Dilution: -$3.37 or -8.4% | I2: =Model!I2
C3: =Model!B3 -> P/TBVS = 108.3% | F3: =Model!E3 -> Cash EPS Accretion: $0.85 or 25.4% | I3: =Model!I3
C4: =Model!B4 -> P/EPS = 24.8 | F4: =Model!E4 -> TBVS Workback: 4 Years | I4: =Model!I4
C5: =Model!B5 -> P/MVS = 124.7% | F5: =Model!E5 -> Cost Savings: $6.2 million or 30.0%
B6: Adapted for GSBC BankSim | C6: =Model!B6 -> 100.0% Stock / 0.0% Cash | F6: =Model!E6 -> Deal Expenses: $4.6 million or 8.0%
B7: Please Complete all Yellow Highlighted Cells for Assumptions
B9: Assumptions (All $ numbers in Millions, except for stock price) | F9: Notes:
B10: Offer price (per share) | C10: 49 | F10: Generally 20-30% over market value: Ensure pricing is reasonable to comparables on Following Tab
B11: Deal Consideration Mix | C11: 1 | D11: Stock | F11: Load Consideration Mix
C12: =1-C11 -> 0 | D12: Cash | F12: Calculated
B13: Cost Savings | C13: 0.3 | F13: 20% to 40% is Typical
B14: Deal Expenses | C14: 0.08 | F14: 7% to 12% is Typical
B15: Deal Expenses % Buyer | C15: 0.9
B16: Credit Mark | C16: 1.5 | F16: 100% - 150% of Target ACL is Typical
B17: CDI (Core Deposit Intangible) | C17: 0.02 | F17: 2% to 4% is Typical
B18: Tax Rate on Transaction | C18: 0.21 | F18: =Model!B7&"'s Tax Rate = "&TEXT(F27,"0.0%")&" / "&Model!D7&"'s Tax Rate = "&TEXT(H27,"0.0%") -> Bank 1 - Bottom of the Barrel Bank's Tax Rate = 20.2% / Bank 4's Tax Rate = 17.6%
B19: Opportunity Cost of Cash | C19: 0.0383 | F19: Use Current Fed Funds Rate in Bank Sim - Report B900
B21: Note: On the Model Tab Please load all Yellow Highlighted Cells
B22: Note: This high level model does not include the impact of interest rate mark nor the accretion of any credit marks
B23: Credit Mark: Used to estimate fair value of loan portfolio.
B24: Engine 1:
B25: Target's Price Per Share | C25: =C10 -> 49 | F25: =C10*Model!D36/(Model!D29-Model!D17)/1000000 -> 1.0830991 | G25: P/TBVS | H25: =C10*Model!D36/Model!D64/1000000 -> 24.847731 | I25: P/EPS
B26: Exchange | C26: =C25/Model!B37 -> 1.1847195 | F26: =C10/Model!D37 -> 1.2471367 | G26: P/MV
F27: =Model!B58/Model!B56 -> 0.20238095 | G27: Buyer's Rate | H27: =Model!D58/Model!D56 -> 0.17647059 | I27: Target's Rates
B29: Target Equity | C29: =Model!D29 -> 52.9
B30: Target Intangibles | C30: =Model!D17 -> 0
B31: Deal Expenses of Target Tax Adjusted | C31: =D63*-1 -> 0.40542611
B32: CDI (Tax Adjusted) | C32: =C17*Model!D20*(1-C18) -> 7.20796
C33: =C29-C30-C31+C32 -> 59.702534
B35: Goodwill | C35: =C10*Model!D36/1000000-C33 -> -2.4065889
B36: Net Goodwill | C36: =C35-C30 -> -2.4065889
B40: Engine 2:
B41: Balance Sheet | C41: CDI | D41: TE Target | E41: TE Buyer | F41: Credit Mark | G41: Purchase Price | H41: Total
B43: Cash Items | C43: 0 | D43: =-C10*Model!D36*C14*(1-C15)/1000000 -> -0.45836756 | E43: =-C10*Model!D36*C14*C15/1000000 -> -4.125308 | G43: =-C10*Model!D36*C12/1000000 -> 0 | H43: =SUM(C43:G43) -> -4.5836756
B44: Federal Funds Sold | H44: =SUM(C44:G44) -> 0
B45: Securities | H45: =SUM(C45:G45) -> 0
B46: Loans (Gross) | F46: =C16*Model!D13 -> -9.3 | H46: =SUM(C46:G46) -> -9.3
B47: Allowance for Credit Losses | F47: =-Model!D13 -> 6.2 | H47: =SUM(C47:G47) -> 6.2
B48: Loans (Net) | C48: =C46+C47 -> 0 | D48: =D46+D47 -> 0 | E48: =E46+E47 -> 0 | F48: =F46+F47 -> -3.1 | G48: =G46+G47 -> 0 | H48: =SUM(C48:G48) -> -3.1
...

Sheet M&A Multiples - Info Only
A1: Valuation M&A Model - M&A Multiples
A6: Tangible Book Acquisition Multiples
B7: 2014 | C7: 2015 | D7: 2016 | E7: 2017 | F7: 2018 | G7: 2019 | H7: 2020 | I7: 2021 | J7: 2022 | K7: 2023 | L7: 2024 | M7: 2025 | N7: 2026 YTD*
A8: National Medians
A9: Bank | B9: 134.38 | C9: 136.99 | D9: 130.63 | E9: 159.02 | F9: 166.325 | G9: 157.71 | H9: 134.76 | I9: 152.23 | J9: 153.87 | K9: 124.165 | L9: 129.42 | M9: 142.935 | N9: 145.675
A11: Regional Medians
A12: Mid-Atlantic Bank | B12: 121.04 | C12: 136.5 | D12: 126.87 | E12: 130.41 | F12: 156.01 | G12: 156.31 | H12: 131.36 | I12: 148.03 | J12: 128.495 | K12: 121.88 | L12: 100.8 | M12: 106.62 | N12: 112.255
A13: Midwest Bank | B13: 135.065 | C13: 125.55 | D13: 125.94 | E13: 157.03 | F13: 156.14 | G13: 148.545 | H13: 127.23 | I13: 153.7 | J13: 153.42 | K13: 127 | L13: 134.62 | M13: 131.13 | N13: 150.8
A14: Northeast Bank | B14: 141.195 | C14: 141.31 | D14: 149.65 | E14: 147.74 | F14: 173.79 | G14: 151.915 | H14: 170.82 | I14: 158.04 | J14: 136.87 | K14: 114.48 | L14: 138.8 | M14: 99.75 | N14: 165.485
A15: Southeast Bank | B15: 136.16 | C15: 141.235 | D15: 130.61 | E15: 161.835 | F15: 178.01 | G15: 158.06 | H15: 129.99 | I15: 151.48 | J15: 172.93 | K15: 132.4 | L15: 132.97 | M15: 166.27 | N15: 193.92
A16: Southwest Bank | B16: 145.33 | C16: 151.84 | D16: 159.73 | E16: 187.14 | F16: 189.12 | G16: 165.73 | H16: 159.52 | I16: 157.09 | J16: 173.67 | K16: 173.14 | L16: 147.67 | M16: 150.86 | N16: 147.365
A17: West Bank | B17: 125.9 | C17: 130.37 | D17: 131.12 | E17: 183.93 | F17: 181.51 | G17: 168.02 | H17: 140.62 | I17: 151.625 | J17: 151.07 | K17: 97.44 | L17: 137.22 | M17: 151.15 | N17: 125.03
A19: Deal Size Medians
A20: <$10 Mil Bank Market Cap | B20: 101.655 | C20: 101.44 | D20: 101.53 | E20: 108.07 | F20: 118.035 | G20: 95 | H20: 112.47 | I20: 151.48 | J20: 125.165 | K20: NA | L20: 65.24 | M20: NA | N20: NA
A21: $10 Mil and $50 Mil Bank Market Cap | B21: 125.93 | C21: 129.755 | D21: 127.535 | E21: 144.23 | F21: 153 | G21: 146.94 | H21: 136.325 | I21: 135.79 | J21: 142.62 | K21: 127 | L21: 128.37 | M21: 126.24 | N21: 127.235
A22: $50 Mil and $100 Mil Bank Market Cap | B22: 145.06 | C22: 144.14 | D22: 161.48 | E22: 189.515 | F22: 178.68 | G22: 162.485 | H22: 139.91 | I22: 147.3 | J22: 154.215 | K22: 135.235 | L22: 128.46 | M22: 123.25 | N22: 127.79
A23: $100 Mil and $500 Mil Bank Market Cap | B23: 174.425 | C23: 174.05 | D23: 165.02 | E23: 188.08 | F23: 188.265 | G23: 171.97 | H23: 151.2 | I23: 155.22 | J23: 167.465 | K23: 114.12 | L23: 132.38 | M23: 151.33 | N23: 158.51
A24: >$500 Mil Bank Market Cap | B24: 147.89 | C24: 221.765 | D24: 211.96 | E24: 237.215 | F24: 235.965 | G24: 159.79 | H24: 144.21 | I24: 166.53 | J24: 125.755 | K24: 114.48 | L24: 146.825 | M24: 161.41 | N24: 180.81
A25: *Note: YTD 2026 as of 05/29/26
A28: Earnings Acquisition Multiples (x)
B29: 2014 | C29: 2015 | D29: 2016 | E29: 2017 | F29: 2018 | G29: 2019 | H29: 2020 | I29: 2021 | J29: 2022 | K29: 2023 | L29: 2024 | M29: 2025 | N29: 2026
A30: National Medians
A31: Bank | B31: 21.82 | C31: 22.45 | D31: 20.025 | E31: 21.435 | F31: 24.015 | G31: 16.05 | H31: 17.12 | I31: 14.935 | J31: 14.325 | K31: 11.08 | L31: 16.35 | M31: 15.425 | N31: 14.18
A33: Regional Medians
A34: Mid-Atlantic Bank | B34: 21.82 | C34: 22.945 | D34: 20.785 | E34: 28.65 | F34: 24.9 | G34: 15.86 | H34: 17.205 | I34: 18 | J34: 16.34 | K34: 10.48 | L34: 16.35 | M34: 16.415 | N34: 25.43
A35: Midwest Bank | B35: 20.99 | C35: 17.93 | D35: 19.58 | E35: 20.07 | F35: 19.94 | G35: 15.22 | H35: 20.95 | I35: 16.285 | J35: 14.29 | K35: 15.555 | L35: 14.5 | M35: 14.3 | N35: 12.12
A36: Northeast Bank | B36: 26.39 | C36: 35.48 | D36: 32.795 | E36: 28.535 | F36: 32.445 | G36: 21.43 | H36: 45.245 | I36: 17.36 | J36: 14.36 | K36: 11.08 | L36: 15.54 | M36: 32.96 | N36: 12.81
A37: Southeast Bank | B37: 23.075 | C37: 22.79 | D37: 19.5 | E37: 22.9 | F37: 24.16 | G37: 16.82 | H37: 14.055 | I37: 13.815 | J37: 14.4 | K37: 10.59 | L37: 16.905 | M37: 14.95 | N37: 15.58
A38: Southwest Bank | B38: 17.1 | C38: 22.07 | D38: 20.95 | E38: 17 | F38: 21.005 | G38: 15.94 | H38: 13.43 | I38: 14.41 | J38: 13.985 | K38: 22.21 | L38: 19.79 | M38: 14.56 | N38: 20.435
A39: West Bank | B39: 23.515 | C39: 23.29 | D39: 23.24 | E39: 21.98 | F39: 25.8 | G39: 15.34 | H39: 16.56 | I39: 14.66 | J39: 13.3 | K39: 9.88 | L39: 16.44 | M39: 17.26 | N39: 33.585
A41: Deal Size Medians
A42: <$10 Mil Bank Market Cap | B42: 27.645 | C42: 18.84 | D42: 24.745 | E42: 25.655 | F42: 14.31 | G42: 16.955 | H42: 33.05 | I42: 43.27 | J42: 29.605 | K42: NA | L42: 20.32 | M42: NA | N42: NA
A43: $10 Mil and $50 Mil Bank Market Cap | B43: 24.83 | C43: 22.79 | D43: 19.79 | E43: 20.63 | F43: 23.37 | G43: 17.57 | H43: 24.07 | I43: 14.66 | J43: 12.94 | K43: 18.79 | L43: 21.11 | M43: 24.06 | N43: 22.065
A44: $50 Mil and $100 Mil Bank Market Cap | B44: 20.33 | C44: 19.005 | D44: 18.455 | E44: 18.64 | F44: 21.3 | G44: 16.37 | H44: 13.71 | I44: 13.81 | J44: 14.75 | K44: 9.73 | L44: 17.19 | M44: 14.22 | N44: 13.86
A45: $100 Mil and $500 Mil Bank Market Cap | B45: 22.225 | C45: 23.47 | D45: 21.49 | E45: 21.05 | F45: 26.995 | G45: 15.4 | H45: 13.43 | I45: 16.275 | J45: 14.38 | K45: 9.275 | L45: 15.38 | M45: 14.62 | N45: 14.13
A46: >$500 Mil Bank Market Cap | B46: 15.405 | C46: 20.31 | D46: 21.67 | E46: 23.37 | F46: 24.885 | G46: 12.605 | H46: 20.97 | I46: 14.82 | J46: 9.87 | K46: 11.08 | L46: 15.4 | M46: 14.61 | N46: 16.225
A47: *Note: YTD 2026 as of 05/29/26
A50: Historical Open Bank M&A Activity
B51: 2014 | C51: 2015 | D51: 2016 | E51: 2017 | F51: 2018 | G51: 2019 | H51: 2020 | I51: 2021 | J51: 2022 | K51: 2023 | L51: 2024 | M51: 2025 | N51: 2026
A53: Aggregate Deal Value ($mil) | B53: 18805.193 | C53: 24515.035 | D53: 26800.448 | E53: 26441.198 | F53: 29609.514 | G53: 55032.177 | H53: 27839.502 | I53: 76731.536 | J53: 8948.6071 | K53: 4140.49 | L53: 16478.57 | M53: 50503.919 | N53: 16978.717
...
